Workbook

Sheet Summary
A1: Store planning model
A2: New store economics, a 3-year plan by channel, and pricing and promotion tests. Built on the Store Copilot demo data, which is synthetic.
A4: How to use
A5: 1. Pick a scenario on the Inputs sheet, cell C4: Base, Upside or Downside.
A6: 2. Change any blue number. Every black number is a formula and updates.
A7: 3. On Pricing, pick a category and test a price change or a promotion.
A8: 4. The Checks sheet works key numbers out a second way. It should say all checks pass.
A10: Blue: an input you can change
A11: Black: a formula
A12: Green: pulled from another sheet
A13: Yellow: the main selectors and levers
A15: Key numbers
A16: Scenario | B16: =scenario -> Base | C16: Checks | D16: =checks_status -> All 13 checks pass
A18: 3-year plan ($K) | B18: Today (run-rate) | C18: 2027 | D18: 2028 | E18: 2029
A19: Revenue | B19: ='3-Year Plan'!B20 -> 19201787 | C19: ='3-Year Plan'!C20 -> 25505722 | D19: ='3-Year Plan'!D20 -> 33382839 | E19: ='3-Year Plan'!E20 -> 41744430
A20: Company EBITDA | B20: ='3-Year Plan'!B35 -> 1071094.8 | C20: ='3-Year Plan'!C35 -> 1461851.8 | D20: ='3-Year Plan'!D35 -> 2230945.6 | E20: ='3-Year Plan'!E35 -> 3110336
A21: EBITDA margin | B21: ='3-Year Plan'!B36 -> 0.055780995 | C21: ='3-Year Plan'!C36 -> 0.05731466 | D21: ='3-Year Plan'!D36 -> 0.066829117 | E21: ='3-Year Plan'!E36 -> 0.074509007
A22: Stores open at year end | B22: ='3-Year Plan'!B7 -> 3 | C22: ='3-Year Plan'!C7 -> 4 | D22: ='3-Year Plan'!D7 -> 5 | E22: ='3-Year Plan'!E7 -> 6
A23: Cash after new-store investment, cumulative | C23: ='3-Year Plan'!C41 -> -888148.18 | D23: ='3-Year Plan'!D41 -> -1007202.5 | E23: ='3-Year Plan'!E41 -> -246866.53
A25: One new store
A26: Total investment | B26: =ns_invest -> 2350000
A27: Mature annual sales | B27: =ns_mature_sales -> 6331186.2
A28: Year 1 sales | B28: ='New Store'!B26 -> 4618041.7
A29: Year 3 store EBITDA | B29: =ns_y3_ebitda -> 722498.7
A30: Payback (months after opening) | B30: =ns_payback -> 48
A31: Year 3 cash-on-cash return | B31: =ns_coc -> 0.30744625
A33: Pricing tests
A34: ="Changing "&category&" prices by "&TEXT(Pricing!B13,"+0%;-0%")&" changes gross profit by "&TEXT(Pricing!B19,"$#,##0;-$#,##0")&" a year (elasticity "&TEXT(Pricing!B14,"0.0")&")." -> Changing Meat & Seafood prices by +3% changes gross profit by $40,496 a year (elasticity -1.2).
A35: =IF(ISNUMBER(Pricing!B42),"A "&TEXT(Pricing!B34,"0%")&" promotion on "&category&" needs "&TEXT(Pricing!B42,"0%")&" more units to pay for itself. Expected: "&TEXT(Pricing!B36,"0%")&".","A "&TEXT(Pricing!B34,"0%")&" promotion on "&category&" sells below cost.") -> A 20% promotion on Meat & Seafood needs 71% more units to pay for itself. Expected: 50%.
A37: What's data and what's assumed
A38: From the demo data (Actuals): sales, cost of goods, margins, waste, basket size, member activity.
A39: Assumed, with a note on Inputs: store sizes, labor, rent, build-out, catering, app orders, membership fees, head office.
A40: Plan years start in January; new stores open at the start of their year.

Sheet Inputs
A1: Inputs
A2: Change the blue cells. Pick a scenario in C4; the Live column feeds every other sheet.
A4: Scenario | C4: Base | D4: Pick Base, Upside or Downside from the list.
A6: Assumption | B6: Unit | C6: Live | D6: Base | E6: Upside | F6: Downside | G6: Last 30 days | H6: Notes
A7: New store
A8: Sales per sq ft vs flagship | B8: % of flagship | C8: =INDEX(D8:F8,MATCH(scenario,$D$6:$F$6,0)) -> 1 | D8: 1 | E8: 1.1 | F8: 0.85 | H8: 100% means the same sales per sq ft as the flagship.
A9: Month 1 sales | B9: % of mature | C9: =INDEX(D9:F9,MATCH(scenario,$D$6:$F$6,0)) -> 0.6 | D9: 0.6 | E9: 0.7 | F9: 0.5 | G9: =IF(s1_per_day=0,0,(s3_per_day/sqft_s3)/(s1_per_day/sqft_s1)) -> 0.6075484 | H9: Last 30 days column: Store 3's sales per sq ft in its first 19 days, vs the flagship.
A10: Months to reach mature sales | B10: months | C10: =INDEX(D10:F10,MATCH(scenario,$D$6:$F$6,0)) -> 18 | D10: 18 | E10: 12 | F10: 24 | H10: The demo data ramps a store in 30 days, which is fast. Real stores take 12 to 24 months.
A11: Gross margin change vs last 30 days | B11: points | C11: =INDEX(D11:F11,MATCH(scenario,$D$6:$F$6,0)) -> 0 | D11: 0 | E11: 0.01 | F11: -0.015 | G11: =gm_actual -> 0.47893261 | H11: Added to each channel's actual margin. The Last 30 days column shows the blended actual.
A12: Waste | B12: % of store sales | C12: =INDEX(D12:F12,MATCH(scenario,$D$6:$F$6,0)) -> 0.019 | D12: =ROUND(waste_actual,3) -> 0.019 | E12: 0.016 | F12: 0.025 | G12: =waste_actual -> 0.018784463 | H12: Base is the actual. The Perishables SOP aims to cut waste.
A13: Store labor | B13: % of sales | C13: =INDEX(D13:F13,MATCH(scenario,$D$6:$F$6,0)) -> 0.19 | D13: 0.19 | E13: 0.18 | F13: 0.21 | H13: Not in the data. The cafe and hot bar make this higher than a typical grocery store.
A14: Labor floor while ramping | B14: % of mature labor | C14: =INDEX(D14:F14,MATCH(scenario,$D$6:$F$6,0)) -> 0.85 | D14: 0.85 | E14: 0.8 | F14: 0.9 | H14: A new store can't cut staff in line with lower early sales.
A15: Rent | B15: $ per sq ft per year | C15: =INDEX(D15:F15,MATCH(scenario,$D$6:$F$6,0)) -> 60 | D15: 60 | E15: 55 | F15: 70 | H15: Not in the data. Assumption.
A16: Other operating costs | B16: % of sales | C16: =INDEX(D16:F16,MATCH(scenario,$D$6:$F$6,0)) -> 0.08 | D16: 0.08 | E16: 0.075 | F16: 0.09 | H16: Card fees, utilities, supplies, repairs, local marketing.
A17: Build-out | B17: $ per sq ft | C17: =INDEX(D17:F17,MATCH(scenario,$D$6:$F$6,0)) -> 250 | D17: 250 | E17: 225 | F17: 300 | H17: Construction, equipment, fixtures.
A18: Pre-opening costs | B18: $ | C18: =INDEX(D18:F18,MATCH(scenario,$D$6:$F$6,0)) -> 150000 | D18: 150000 | E18: 125000 | F18: 200000 | H18: Hiring, training, launch marketing.
A20: Growth
A21: Grocery sales growth, existing stores | B21: % per year | C21: =INDEX(D21:F21,MATCH(scenario,$D$6:$F$6,0)) -> 0.04 | D21: 0.04 | E21: 0.07 | F21: 0.01
A22: Cafe and hot bar growth, existing stores | B22: % per year | C22: =INDEX(D22:F22,MATCH(scenario,$D$6:$F$6,0)) -> 0.08 | D22: 0.08 | E22: 0.12 | F22: 0.03
A23: New stores opened in 2027 | B23: stores | C23: =INDEX(D23:F23,MATCH(scenario,$D$6:$F$6,0)) -> 1 | D23: 1 | E23: 1 | F23: 0 | H23: Opened at the start of the year; each follows the New Store sheet.
A24: New stores opened in 2028 | B24: stores | C24: =INDEX(D24:F24,MATCH(scenario,$D$6:$F$6,0)) -> 1 | D24: 1 | E24: 2 | F24: 1
A25: New stores opened in 2029 | B25: stores | C25: =INDEX(D25:F25,MATCH(scenario,$D$6:$F$6,0)) -> 1 | D25: 1 | E25: 2 | F25: 0
A26: Catering sales in 2027 | B26: $ | C26: =INDEX(D26:F26,MATCH(scenario,$D$6:$F$6,0)) -> 250000 | D26: 250000 | E26: 400000 | F26: 100000 | H26: New channel. Not in the data.
A27: Catering growth | B27: % per year | C27: =INDEX(D27:F27,MATCH(scenario,$D$6:$F$6,0)) -> 0.3 | D27: 0.3 | E27: 0.5 | F27: 0.1
A28: Catering contribution margin | B28: % after food and labor | C28: =INDEX(D28:F28,MATCH(scenario,$D$6:$F$6,0)) -> 0.25 | D28: 0.25 | E28: 0.3 | F28: 0.2
A29: App orders: extra sales by 2029 | B29: % of store sales | C29: =INDEX(D29:F29,MATCH(scenario,$D$6:$F$6,0)) -> 0.04 | D29: 0.04 | E29: 0.06 | F29: 0.02 | H29: Only sales the app adds, not orders that move from the store to the app.
A30: App fulfillment cost | B30: % of app sales | C30: =INDEX(D30:F30,MATCH(scenario,$D$6:$F$6,0)) -> 0.12 | D30: 0.12 | E30: 0.1 | F30: 0.15 | H30: Picking, packing, delivery subsidy.
A32: Membership
A33: Member growth | B33: % per year | C33: =INDEX(D33:F33,MATCH(scenario,$D$6:$F$6,0)) -> 0.2 | D33: 0.2 | E33: 0.35 | F33: 0.1
A34: Members who pay a fee | B34: % of members | C34: =INDEX(D34:F34,MATCH(scenario,$D$6:$F$6,0)) -> 0.25 | D34: 0.25 | E34: 0.35 | F34: 0.15
A35: Member perks cost | B35: % of fees | C35: =INDEX(D35:F35,MATCH(scenario,$D$6:$F$6,0)) -> 0.3 | D35: 0.3 | E35: 0.25 | F35: 0.4
A37: Company
A38: Head office costs | B38: % of revenue | C38: =INDEX(D38:F38,MATCH(scenario,$D$6:$F$6,0)) -> 0.05 | D38: 0.05 | E38: 0.045 | F38: 0.06 | H38: Finance, buying, marketing, leadership. Not in the data.
A40: Same in every scenario
A41: Flagship size | B41: sq ft | C41: 12000 | H41: Store sizes are not in the data. Assumption.
A42: Store 2 size | B42: sq ft | C42: 8500
A43: Store 3 size | B43: sq ft | C43: 6500
A44: New store size | B44: sq ft | C44: 8000
A45: Opening inventory | B45: $ | C45: 200000
A46: Member visits per month | B46: visits | C46: 4 | H46: Turns member transactions into a member count.
...

Sheet Actuals
A1: Actuals
A2: Last 30 days of the demo data, 2026-08-30 to 2026-09-28. Synthetic. Pasted from store.db by planning/build_workbook.py. Blue = pasted value, black = formula.
A3: Days in window | B3: 30
A5: By store
A6: Store | B6: Days open | C6: Sales, item lines | D6: Sales, POS transactions | E6: Cost of goods | F6: Gross margin | G6: Transactions | H6: Member transactions | I6: Average basket | J6: Member share | K6: Waste cost | L6: Waste, % of sales | M6: Sales per open day | N6: Annual run-rate
A7: Flagship (Downtown) | B7: 30 | C7: 780557.2 | D7: 780557.2 | E7: 408581.18 | F7: =IF(C7=0,0,(C7-E7)/C7) -> 0.4765519 | G7: 16626 | H7: 3247 | I7: =IF(G7=0,0,C7/G7) -> 46.947985 | J7: =IF(G7=0,0,H7/G7) -> 0.19529652 | K7: 14536.36 | L7: =IF(C7=0,0,K7/C7) -> 0.018623055 | M7: =IF(B7=0,0,C7/B7) -> 26018.573 | N7: =M7*365 -> 9496779.3
A8: Store 2 (Coconut Grove, hypothetical) | B8: 30 | C8: 540799.27 | D8: 540799.27 | E8: 280733.65 | F8: =IF(C8=0,0,(C8-E8)/C8) -> 0.48089122 | G8: 11914 | H8: 2373 | I8: =IF(G8=0,0,C8/G8) -> 45.391915 | J8: =IF(G8=0,0,H8/G8) -> 0.19917744 | K8: 10147.67 | L8: =IF(C8=0,0,K8/C8) -> 0.018764208 | M8: =IF(B8=0,0,C8/B8) -> 18026.642 | N8: =M8*365 -> 6579724.5
A9: Store 3 (Miami Beach, hypothetical) | B9: 19 | C9: 162685.96 | D9: 162685.96 | E9: 83971.29 | F9: =IF(C9=0,0,(C9-E9)/C9) -> 0.48384427 | G9: 3703 | H9: 763 | I9: =IF(G9=0,0,C9/G9) -> 43.933557 | J9: =IF(G9=0,0,H9/G9) -> 0.20604915 | K9: 3192.91 | L9: =IF(C9=0,0,K9/C9) -> 0.019626217 | M9: =IF(B9=0,0,C9/B9) -> 8562.4189 | N9: =M9*365 -> 3125282.9
A10: Total | C10: =SUM(C7:C9) -> 1484042.4 | D10: =SUM(D7:D9) -> 1484042.4 | E10: =SUM(E7:E9) -> 773286.12 | F10: =IF(C10=0,0,(C10-E10)/C10) -> 0.47893261 | G10: =SUM(G7:G9) -> 32243 | H10: =SUM(H7:H9) -> 6383 | I10: =IF(G10=0,0,C10/G10) -> 46.02681 | J10: =IF(G10=0,0,H10/G10) -> 0.19796545 | K10: =SUM(K7:K9) -> 27876.94 | L10: =IF(C10=0,0,K10/C10) -> 0.018784463 | M10: =SUM(M7:M9) -> 52607.635 | N10: =SUM(N7:N9) -> 19201787
A11: Store 3 opened recently: 19 days in the window, so its run-rate understates a full year.
A13: By category
A14: Category | B14: Channel | C14: Sales | D14: Cost of goods | E14: Units | F14: Gross margin | G14: Target margin | H14: Gap to target | I14: Average price | J14: Average unit cost | K14: Units per week | L14: Share of sales
A15: Produce | B15: Grocery | C15: 127119.22 | D15: 86444.96 | E15: 25878 | F15: =IF(C15=0,0,(C15-D15)/C15) -> 0.3199694 | G15: 0.35 | H15: =F15-G15 -> -0.030030604 | I15: =IF(E15=0,0,C15/E15) -> 4.9122506 | J15: =IF(E15=0,0,D15/E15) -> 3.3404807 | K15: =E15/days_window*7 -> 6038.2 | L15: =IF($C$25=0,0,C15/$C$25) -> 0.085657403
A16: Meat & Seafood | B16: Grocery | C16: 164813.46 | D16: 125124.29 | E16: 5154 | F16: =IF(C16=0,0,(C16-D16)/C16) -> 0.24081267 | G16: 0.28 | H16: =F16-G16 -> -0.039187326 | I16: =IF(E16=0,0,C16/E16) -> 31.977776 | J16: =IF(E16=0,0,D16/E16) -> 24.277123 | K16: =E16/days_window*7 -> 1202.6 | L16: =IF($C$25=0,0,C16/$C$25) -> 0.11105711
A17: Dairy & Eggs | B17: Grocery | C17: 71979.37 | D17: 48884.55 | E17: 8763 | F17: =IF(C17=0,0,(C17-D17)/C17) -> 0.32085332 | G17: 0.32 | H17: =F17-G17 -> 0.00085332228 | I17: =IF(E17=0,0,C17/E17) -> 8.21401 | J17: =IF(E17=0,0,D17/E17) -> 5.5785176 | K17: =E17/days_window*7 -> 2044.7 | L17: =IF($C$25=0,0,C17/$C$25) -> 0.048502232
A18: Pantry | B18: Grocery | C18: 141755.02 | D18: 86547.4 | E18: 12198 | F18: =IF(C18=0,0,(C18-D18)/C18) -> 0.38945795 | G18: 0.38 | H18: =F18-G18 -> 0.0094579536 | I18: =IF(E18=0,0,C18/E18) -> 11.621169 | J18: =IF(E18=0,0,D18/E18) -> 7.0952123 | K18: =E18/days_window*7 -> 2846.2 | L18: =IF($C$25=0,0,C18/$C$25) -> 0.09551952
A19: Snacks | B19: Grocery | C19: 67439.28 | D19: 39513.74 | E19: 9272 | F19: =IF(C19=0,0,(C19-D19)/C19) -> 0.4140842 | G19: 0.4 | H19: =F19-G19 -> 0.014084195 | I19: =IF(E19=0,0,C19/E19) -> 7.273434 | J19: =IF(E19=0,0,D19/E19) -> 4.2616199 | K19: =E19/days_window*7 -> 2163.4667 | L19: =IF($C$25=0,0,C19/$C$25) -> 0.045442959
A20: Beverages & Juices | B20: Grocery | C20: 130830.96 | D20: 71061.85 | E20: 14704 | F20: =IF(C20=0,0,(C20-D20)/C20) -> 0.45684225 | G20: 0.45 | H20: =F20-G20 -> 0.006842249 | I20: =IF(E20=0,0,C20/E20) -> 8.8976442 | J20: =IF(E20=0,0,D20/E20) -> 4.8328244 | K20: =E20/days_window*7 -> 3430.9333 | L20: =IF($C$25=0,0,C20/$C$25) -> 0.088158504
A21: Cafe & Hot Bar | B21: Cafe & hot bar | C21: 557894.52 | D21: 206716.08 | E21: 32648 | F21: =IF(C21=0,0,(C21-D21)/C21) -> 0.62947103 | G21: 0.65 | H21: =F21-G21 -> -0.020528967 | I21: =IF(E21=0,0,C21/E21) -> 17.088168 | J21: =IF(E21=0,0,D21/E21) -> 6.3316614 | K21: =E21/days_window*7 -> 7617.8667 | L21: =IF($C$25=0,0,C21/$C$25) -> 0.37592896
A22: Supplements | B22: Grocery | C22: 145531.14 | D22: 74268.65 | E22: 2986 | F22: =IF(C22=0,0,(C22-D22)/C22) -> 0.48967176 | G22: 0.48 | H22: =F22-G22 -> 0.0096717637 | I22: =IF(E22=0,0,C22/E22) -> 48.737823 | J22: =IF(E22=0,0,D22/E22) -> 24.872287 | K22: =E22/days_window*7 -> 696.73333 | L22: =IF($C$25=0,0,C22/$C$25) -> 0.098064002
A23: Beauty & Body | B23: Grocery | C23: 70906.6 | D23: 31261.32 | E23: 1540 | F23: =IF(C23=0,0,(C23-D23)/C23) -> 0.55911974 | G23: 0.55 | H23: =F23-G23 -> 0.0091197434 | I23: =IF(E23=0,0,C23/E23) -> 46.043247 | J23: =IF(E23=0,0,D23/E23) -> 20.299558 | K23: =E23/days_window*7 -> 359.33333 | L23: =IF($C$25=0,0,C23/$C$25) -> 0.047779362
A24: Unmapped POS codes | B24: Grocery | C24: 5772.86 | D24: 3463.28 | E24: 314 | F24: =IF(C24=0,0,(C24-D24)/C24) -> 0.40007553 | I24: =IF(E24=0,0,C24/E24) -> 18.384904 | J24: =IF(E24=0,0,D24/E24) -> 11.029554 | K24: =E24/days_window*7 -> 73.266667 | L24: =IF($C$25=0,0,C24/$C$25) -> 0.0038899562
A25: Total | C25: =SUM(C15:C24) -> 1484042.4 | D25: =SUM(D15:D24) -> 773286.12 | E25: =SUM(E15:E24) -> 113457 | F25: =IF(C25=0,0,(C25-D25)/C25) -> 0.47893261
A26: Unmapped POS codes are sales the POS can't tie to a product; counted as grocery.
A28: By channel
A29: Channel | B29: Sales | C29: Cost of goods | D29: Gross margin | E29: Share of sales | F29: Annual run-rate
A30: Grocery | B30: =SUMIF($B$15:$B$24,"Grocery",$C$15:$C$24) -> 926147.91 | C30: =SUMIF($B$15:$B$24,"Grocery",$D$15:$D$24) -> 566570.04 | D30: =IF(B30=0,0,(B30-C30)/B30) -> 0.38825102 | E30: =IF($C$25=0,0,B30/$C$25) -> 0.62407104 | F30: =E30*stores_runrate -> 11983279
A31: Cafe & hot bar | B31: =SUMIF($B$15:$B$24,"Cafe & hot bar",$C$15:$C$24) -> 557894.52 | C31: =SUMIF($B$15:$B$24,"Cafe & hot bar",$D$15:$D$24) -> 206716.08 | D31: =IF(B31=0,0,(B31-C31)/B31) -> 0.62947103 | E31: =IF($C$25=0,0,B31/$C$25) -> 0.37592896 | F31: =E31*stores_runrate -> 7218507.6
A32: Run-rate splits the stores' annual run-rate by each channel's share of sales.

Sheet New Store
A1: New store
A2: ="One new store, month by month for 5 years. Scenario: "&scenario -> One new store, month by month for 5 years. Scenario: Base
A4: Drivers
A5: Store size (sq ft) | B5: =sqft_new -> 8000
A6: Flagship sales, annual run-rate | B6: =flag_runrate -> 9496779.3
A7: Flagship size (sq ft) | B7: =sqft_s1 -> 12000
A8: Flagship sales per sq ft | B8: =IF(B7=0,0,B6/B7) -> 791.39827
A9: Sales per sq ft vs flagship | B9: =prod -> 1
A10: Mature annual sales | B10: =B5*B8*B9 -> 6331186.2
A11: Gross margin | B11: =gm_actual+gm_delta -> 0.47893261
A12: Build-out | B12: =B5*buildout_psf -> 2000000
A13: Pre-opening costs | B13: =preopen -> 150000
A14: Opening inventory | B14: =inventory -> 200000
A15: Total investment | B15: =SUM(B12:B14) -> 2350000
A17: Results
A18: Payback (months after opening) | B18: =IF(MIN($D59:$BK59)>60,"Over 60",MIN($D59:$BK59)) -> 48
A19: Year 3 store EBITDA | B19: =D32 -> 722498.7
A20: Year 3 cash-on-cash return | B20: =IF(ns_invest=0,0,D32/ns_invest) -> 0.30744625
A21: Sales per sq ft at maturity | B21: =IF(B5=0,0,ns_mature_sales/B5) -> 791.39827
A22: Store EBITDA margin at maturity | B22: =IF(ns_mature_sales=0,0,ns_gm-waste_pct-labor_pct-other_pct-sqft_new*rent_psf/ns_mature_sales) -> 0.11411743
A24: By store year
B25: 1 | C25: 2 | D25: 3 | E25: 4 | F25: 5
A26: Sales | B26: =SUMIF($D$47:$BK$47,B$25,$D49:$BK49) -> 4618041.7 | C26: =SUMIF($D$47:$BK$47,C$25,$D49:$BK49) -> 6144974.8 | D26: =SUMIF($D$47:$BK$47,D$25,$D49:$BK49) -> 6331186.2 | E26: =SUMIF($D$47:$BK$47,E$25,$D49:$BK49) -> 6331186.2 | F26: =SUMIF($D$47:$BK$47,F$25,$D49:$BK49) -> 6331186.2
A27: Gross profit | B27: =SUMIF($D$47:$BK$47,B$25,$D50:$BK50) -> 2211730.7 | C27: =SUMIF($D$47:$BK$47,C$25,$D50:$BK50) -> 2943028.8 | D27: =SUMIF($D$47:$BK$47,D$25,$D50:$BK50) -> 3032211.5 | E27: =SUMIF($D$47:$BK$47,E$25,$D50:$BK50) -> 3032211.5 | F27: =SUMIF($D$47:$BK$47,F$25,$D50:$BK50) -> 3032211.5
A28: Waste | B28: =SUMIF($D$47:$BK$47,B$25,$D51:$BK51) -> 87742.792 | C28: =SUMIF($D$47:$BK$47,C$25,$D51:$BK51) -> 116754.52 | D28: =SUMIF($D$47:$BK$47,D$25,$D51:$BK51) -> 120292.54 | E28: =SUMIF($D$47:$BK$47,E$25,$D51:$BK51) -> 120292.54 | F28: =SUMIF($D$47:$BK$47,F$25,$D51:$BK51) -> 120292.54
A29: Labor | B29: =SUMIF($D$47:$BK$47,B$25,$D52:$BK52) -> 1023371.1 | C29: =SUMIF($D$47:$BK$47,C$25,$D52:$BK52) -> 1167545.2 | D29: =SUMIF($D$47:$BK$47,D$25,$D52:$BK52) -> 1202925.4 | E29: =SUMIF($D$47:$BK$47,E$25,$D52:$BK52) -> 1202925.4 | F29: =SUMIF($D$47:$BK$47,F$25,$D52:$BK52) -> 1202925.4
A30: Rent | B30: =SUMIF($D$47:$BK$47,B$25,$D53:$BK53) -> 480000 | C30: =SUMIF($D$47:$BK$47,C$25,$D53:$BK53) -> 480000 | D30: =SUMIF($D$47:$BK$47,D$25,$D53:$BK53) -> 480000 | E30: =SUMIF($D$47:$BK$47,E$25,$D53:$BK53) -> 480000 | F30: =SUMIF($D$47:$BK$47,F$25,$D53:$BK53) -> 480000
A31: Other operating costs | B31: =SUMIF($D$47:$BK$47,B$25,$D54:$BK54) -> 369443.33 | C31: =SUMIF($D$47:$BK$47,C$25,$D54:$BK54) -> 491597.99 | D31: =SUMIF($D$47:$BK$47,D$25,$D54:$BK54) -> 506494.89 | E31: =SUMIF($D$47:$BK$47,E$25,$D54:$BK54) -> 506494.89 | F31: =SUMIF($D$47:$BK$47,F$25,$D54:$BK54) -> 506494.89
A32: Store EBITDA (4-wall) | B32: =SUMIF($D$47:$BK$47,B$25,$D55:$BK55) -> 251173.54 | C32: =SUMIF($D$47:$BK$47,C$25,$D55:$BK55) -> 687131.09 | D32: =SUMIF($D$47:$BK$47,D$25,$D55:$BK55) -> 722498.7 | E32: =SUMIF($D$47:$BK$47,E$25,$D55:$BK55) -> 722498.7 | F32: =SUMIF($D$47:$BK$47,F$25,$D55:$BK55) -> 722498.7
A33: Store EBITDA margin | B33: =IF(B26=0,0,B32/B26) -> 0.054389623 | C33: =IF(C26=0,0,C32/C26) -> 0.11182 | D33: =IF(D26=0,0,D32/D26) -> 0.11411743 | E33: =IF(E26=0,0,E32/E26) -> 0.11411743 | F33: =IF(F26=0,0,F32/F26) -> 0.11411743
A34: Cumulative cash at year end | B34: =INDEX($D58:$BK58,MATCH(B25*12,$D$46:$BK$46,0)) -> -2098826.5 | C34: =INDEX($D58:$BK58,MATCH(C25*12,$D$46:$BK$46,0)) -> -1411695.4 | D34: =INDEX($D58:$BK58,MATCH(D25*12,$D$46:$BK$46,0)) -> -689196.67 | E34: =INDEX($D58:$BK58,MATCH(E25*12,$D$46:$BK$46,0)) -> 33302.025 | F34: =INDEX($D58:$BK58,MATCH(F25*12,$D$46:$BK$46,0)) -> 755800.72
A36: Sensitivity: store EBITDA in a mature year
A37: Rows move sales per sq ft, columns move gross margin, around the live scenario (center).
A38: Sales per sq ft vs flagship / gross margin | B38: =ns_gm-0.02 -> 0.45893261 | C38: =ns_gm-0.01 -> 0.46893261 | D38: =ns_gm -> 0.47893261 | E38: =ns_gm+0.01 -> 0.48893261 | F38: =ns_gm+0.02 -> 0.49893261
A39: =prod-0.2 -> 0.8 | B39: =$B$5*$B$8*$A39*(B$38-waste_pct-labor_pct-other_pct)-$B$5*rent_psf -> 380699.98 | C39: =$B$5*$B$8*$A39*(C$38-waste_pct-labor_pct-other_pct)-$B$5*rent_psf -> 431349.47 | D39: =$B$5*$B$8*$A39*(D$38-waste_pct-labor_pct-other_pct)-$B$5*rent_psf -> 481998.96 | E39: =$B$5*$B$8*$A39*(E$38-waste_pct-labor_pct-other_pct)-$B$5*rent_psf -> 532648.45 | F39: =$B$5*$B$8*$A39*(F$38-waste_pct-labor_pct-other_pct)-$B$5*rent_psf -> 583297.94
A40: =prod-0.1 -> 0.9 | B40: =$B$5*$B$8*$A40*(B$38-waste_pct-labor_pct-other_pct)-$B$5*rent_psf -> 488287.48 | C40: =$B$5*$B$8*$A40*(C$38-waste_pct-labor_pct-other_pct)-$B$5*rent_psf -> 545268.15 | D40: =$B$5*$B$8*$A40*(D$38-waste_pct-labor_pct-other_pct)-$B$5*rent_psf -> 602248.83 | E40: =$B$5*$B$8*$A40*(E$38-waste_pct-labor_pct-other_pct)-$B$5*rent_psf -> 659229.5 | F40: =$B$5*$B$8*$A40*(F$38-waste_pct-labor_pct-other_pct)-$B$5*rent_psf -> 716210.18
A41: =prod -> 1 | B41: =$B$5*$B$8*$A41*(B$38-waste_pct-labor_pct-other_pct)-$B$5*rent_psf -> 595874.97 | C41: =$B$5*$B$8*$A41*(C$38-waste_pct-labor_pct-other_pct)-$B$5*rent_psf -> 659186.83 | D41: =$B$5*$B$8*$A41*(D$38-waste_pct-labor_pct-other_pct)-$B$5*rent_psf -> 722498.7 | E41: =$B$5*$B$8*$A41*(E$38-waste_pct-labor_pct-other_pct)-$B$5*rent_psf -> 785810.56 | F41: =$B$5*$B$8*$A41*(F$38-waste_pct-labor_pct-other_pct)-$B$5*rent_psf -> 849122.42
A42: =prod+0.1 -> 1.1 | B42: =$B$5*$B$8*$A42*(B$38-waste_pct-labor_pct-other_pct)-$B$5*rent_psf -> 703462.47 | C42: =$B$5*$B$8*$A42*(C$38-waste_pct-labor_pct-other_pct)-$B$5*rent_psf -> 773105.52 | D42: =$B$5*$B$8*$A42*(D$38-waste_pct-labor_pct-other_pct)-$B$5*rent_psf -> 842748.57 | E42: =$B$5*$B$8*$A42*(E$38-waste_pct-labor_pct-other_pct)-$B$5*rent_psf -> 912391.61 | F42: =$B$5*$B$8*$A42*(F$38-waste_pct-labor_pct-other_pct)-$B$5*rent_psf -> 982034.66
A43: =prod+0.2 -> 1.2 | B43: =$B$5*$B$8*$A43*(B$38-waste_pct-labor_pct-other_pct)-$B$5*rent_psf -> 811049.97 | C43: =$B$5*$B$8*$A43*(C$38-waste_pct-labor_pct-other_pct)-$B$5*rent_psf -> 887024.2 | D43: =$B$5*$B$8*$A43*(D$38-waste_pct-labor_pct-other_pct)-$B$5*rent_psf -> 962998.44 | E43: =$B$5*$B$8*$A43*(E$38-waste_pct-labor_pct-other_pct)-$B$5*rent_psf -> 1038972.7 | F43: =$B$5*$B$8*$A43*(F$38-waste_pct-labor_pct-other_pct)-$B$5*rent_psf -> 1114946.9
A45: Month by month
...

Sheet 3-Year Plan
A1: 3-Year Plan
A2: ="Existing stores grow from today's run-rate; new stores follow the New Store sheet. Scenario: "&scenario -> Existing stores grow from today's run-rate; new stores follow the New Store sheet. Scenario: Base
A3: All amounts in $K.
B4: Today (run-rate) | C4: 2027 | D4: 2028 | E4: 2029 | F4: Notes
A5: Drivers
A6: New stores opened | C6: =open_2027 -> 1 | D6: =open_2028 -> 1 | E6: =open_2029 -> 1
A7: Stores open at year end | B7: =COUNTA(Actuals!$A$7:$A$9) -> 3 | C7: =B7+C6 -> 4 | D7: =C7+D6 -> 5 | E7: =D7+E6 -> 6
A8: Selling space (sq ft) | B8: =sqft_s1+sqft_s2+sqft_s3 -> 27000 | C8: =B8+C6*sqft_new -> 35000 | D8: =C8+D6*sqft_new -> 43000 | E8: =D8+E6*sqft_new -> 51000
A9: App ramp, share of 2029 level | C9: =app_ramp_27 -> 0.33333333 | D9: =app_ramp_28 -> 0.66666667 | E9: =app_ramp_29 -> 1
A10: Active members (estimate) | B10: =member_tx/visits -> 1595.75 | C10: =B10*(1+g_members) -> 1914.9 | D10: =C10*(1+g_members) -> 2297.88 | E10: =D10*(1+g_members) -> 2757.456 | F10: Today: member transactions in the last 30 days divided by visits per member per month.
A11: Paying members | B11: 0 | C11: =C10*paid_conv -> 478.725 | D11: =D10*paid_conv -> 574.47 | E11: =E10*paid_conv -> 689.364 | F11: Assumes no paid tier today.
A13: Revenue
A14: Grocery, existing stores | B14: =grocery_runrate -> 11983279 | C14: =B14*(1+g_grocery) -> 12462610 | D14: =C14*(1+g_grocery) -> 12961115 | E14: =D14*(1+g_grocery) -> 13479559
A15: Cafe and hot bar, existing stores | B15: =cafe_runrate -> 7218507.6 | C15: =B15*(1+g_cafe) -> 7795988.2 | D15: =C15*(1+g_cafe) -> 8419667.2 | E15: =D15*(1+g_cafe) -> 9093240.6 | F15: Existing stores include Store 3, which is still ramping, so this is conservative.
A16: New stores | B16: 0 | C16: ='New Store'!$B$26*C$6 -> 4618041.7 | D16: ='New Store'!$C$26*C$6+'New Store'!$B$26*D$6 -> 10763017 | E16: ='New Store'!$D$26*C$6+'New Store'!$C$26*D$6+'New Store'!$B$26*E$6 -> 17094203 | F16: Each year adds that year's openings at year-1 sales and earlier openings at their later-year sales.
A17: Catering | B17: 0 | C17: =cat_y1 -> 250000 | D17: =C17*(1+g_cat) -> 325000 | E17: =D17*(1+g_cat) -> 422500 | F17: Not in the data yet.
A18: App orders (extra sales) | B18: 0 | C18: =(C14+C15+C16)*app_pct*C9 -> 331688.53 | D18: =(D14+D15+D16)*app_pct*D9 -> 857167.96 | E18: =(E14+E15+E16)*app_pct*E9 -> 1586680.1
A19: Membership fees | B19: =B11*fee -> 0 | C19: =C11*fee -> 47393.775 | D19: =D11*fee -> 56872.53 | E19: =E11*fee -> 68247.036
A20: Total revenue | B20: =SUM(B14:B19) -> 19201787 | C20: =SUM(C14:C19) -> 25505722 | D20: =SUM(D14:D19) -> 33382839 | E20: =SUM(E14:E19) -> 41744430
A21: Growth | C21: =IF(B20=0,0,C20/B20-1) -> 0.32829944 | D21: =IF(C20=0,0,D20/C20-1) -> 0.30883722 | E21: =IF(D20=0,0,E20/D20-1) -> 0.25047573
A23: Profit
A24: Existing stores: gross profit | B24: =B14*grocery_gm+B15*cafe_gm -> 9196361.7 | C24: =C14*(grocery_gm+gm_delta)+C15*(cafe_gm+gm_delta) -> 9745969.9 | D24: =D14*(grocery_gm+gm_delta)+D15*(cafe_gm+gm_delta) -> 10332103 | E24: =E14*(grocery_gm+gm_delta)+E15*(cafe_gm+gm_delta) -> 10957384 | F24: Today uses actual margins; later years add the margin change from Inputs.
A25: Existing stores: waste | B25: =(B14+B15)*waste_actual -> 360695.25 | C25: =(C14+C15)*waste_pct -> 384913.37 | D25: =(D14+D15)*waste_pct -> 406234.86 | E25: =(E14+E15)*waste_pct -> 428883.2
A26: Existing stores: labor | B26: =(B14+B15)*labor_pct_base -> 3648339.5 | C26: =(C14+C15)*labor_pct -> 3849133.7 | D26: =(D14+D15)*labor_pct -> 4062348.6 | E26: =(E14+E15)*labor_pct -> 4288832 | F26: Labor, rent and other costs aren't in the data. Today uses the Base assumptions in every scenario.
A27: Existing stores: rent | B27: =(sqft_s1+sqft_s2+sqft_s3)*rent_psf_base -> 1620000 | C27: =(sqft_s1+sqft_s2+sqft_s3)*rent_psf -> 1620000 | D27: =(sqft_s1+sqft_s2+sqft_s3)*rent_psf -> 1620000 | E27: =(sqft_s1+sqft_s2+sqft_s3)*rent_psf -> 1620000
A28: Existing stores: other operating costs | B28: =(B14+B15)*other_pct_base -> 1536142.9 | C28: =(C14+C15)*other_pct -> 1620687.9 | D28: =(D14+D15)*other_pct -> 1710462.5 | E28: =(E14+E15)*other_pct -> 1805824
A29: Existing stores: EBITDA (4-wall) | B29: =B24-B25-B26-B27-B28 -> 2031184.1 | C29: =C24-C25-C26-C27-C28 -> 2271234.9 | D29: =D24-D25-D26-D27-D28 -> 2533056.6 | E29: =E24-E25-E26-E27-E28 -> 2813845
A30: New stores: EBITDA (4-wall) | B30: 0 | C30: ='New Store'!$B$32*C$6 -> 251173.54 | D30: ='New Store'!$C$32*C$6+'New Store'!$B$32*D$6 -> 938304.63 | E30: ='New Store'!$D$32*C$6+'New Store'!$C$32*D$6+'New Store'!$B$32*E$6 -> 1660803.3
A31: Catering contribution | B31: =B17*cat_margin -> 0 | C31: =C17*cat_margin -> 62500 | D31: =D17*cat_margin -> 81250 | E31: =E17*cat_margin -> 105625
A32: App orders contribution | B32: =B18*(gm_actual+gm_delta-app_cost) -> 0 | C32: =C18*(gm_actual+gm_delta-app_cost) -> 119053.83 | D32: =D18*(gm_actual+gm_delta-app_cost) -> 307665.53 | E32: =E18*(gm_actual+gm_delta-app_cost) -> 569511.23
A33: Membership, net of perks | B33: =B19*(1-perks_cost) -> 0 | C33: =C19*(1-perks_cost) -> 33175.643 | D33: =D19*(1-perks_cost) -> 39810.771 | E33: =E19*(1-perks_cost) -> 47772.925
A34: Head office costs | B34: =B20*ho_pct_base -> 960089.33 | C34: =C20*ho_pct -> 1275286.1 | D34: =D20*ho_pct -> 1669141.9 | E34: =E20*ho_pct -> 2087221.5
A35: Company EBITDA | B35: =B29+B30+B31+B32+B33-B34 -> 1071094.8 | C35: =C29+C30+C31+C32+C33-C34 -> 1461851.8 | D35: =D29+D30+D31+D32+D33-D34 -> 2230945.6 | E35: =E29+E30+E31+E32+E33-E34 -> 3110336
A36: EBITDA margin | B36: =IF(B20=0,0,B35/B20) -> 0.055780995 | C36: =IF(C20=0,0,C35/C20) -> 0.05731466 | D36: =IF(D20=0,0,D35/D20) -> 0.066829117 | E36: =IF(E20=0,0,E35/E20) -> 0.074509007
A38: Cash
A39: New store investment | C39: =C6*ns_invest -> 2350000 | D39: =D6*ns_invest -> 2350000 | E39: =E6*ns_invest -> 2350000
A40: Cash after investment | C40: =C35-C39 -> -888148.18 | D40: =D35-D39 -> -119054.37 | E40: =E35-E39 -> 760336.02
A41: Cumulative, from 2027 | C41: =C40 -> -888148.18 | D41: =C41+D40 -> -1007202.5 | E41: =D41+E40 -> -246866.53

Sheet Pricing
A1: Pricing
A2: Test a price change or a promotion on one category, using its last-30-day price, cost and volume.
A4: Category | B4: Meat & Seafood | D4: Pick a category from the list.
A6: Price change
A7: Average shelf price | B7: =INDEX(Actuals!$I$15:$I$24,MATCH(category,Actuals!$A$15:$A$24,0)) -> 31.977776
A8: Average unit cost | B8: =INDEX(Actuals!$J$15:$J$24,MATCH(category,Actuals!$A$15:$A$24,0)) -> 24.277123
A9: Units per week, all stores | B9: =INDEX(Actuals!$K$15:$K$24,MATCH(category,Actuals!$A$15:$A$24,0)) -> 1202.6
A10: Gross margin now | B10: =IF(B7=0,0,(B7-B8)/B7) -> 0.24081267
A11: Target margin | B11: =INDEX(Actuals!$G$15:$G$24,MATCH(category,Actuals!$A$15:$A$24,0)) -> 0.28 | C11: From the Pricing and Margin Policy.
A12: Gap to target | B12: =B10-B11 -> -0.039187326
A13: Price change | B13: 0.03
A14: Price elasticity | B14: -1.2 | C14: -1.2 means a 1% price rise loses 1.2% of units. Not measured in the demo data; grocery is often -0.5 to -2.5.
A15: New price | B15: =B7*(1+B13) -> 32.93711
A16: Units per week after | B16: =MAX(0,B9*(1+B14*B13)) -> 1159.3064
A17: Gross profit per week, now | B17: =(B7-B8)*B9 -> 9260.8063
A18: Gross profit per week, after | B18: =(B15-B8)*B16 -> 10039.579
A19: Change in gross profit per year | B19: =(B18-B17)*52 -> 40496.154
A20: New gross margin | B20: =IF(B15=0,0,(B15-B8)/B15) -> 0.26292493
A21: Break-even change in units | B21: =IF(B15-B8<=0,"Below cost",(B7-B8)/(B15-B8)-1) -> -0.11077768 | C21: The unit change that leaves gross profit flat. Compare it with the expected change.
A23: Change in gross profit per year: price change (rows) by elasticity (columns)
B24: -0.5 | C24: -1 | D24: -1.5 | E24: -2 | F24: -2.5
A25: -0.06 | B25: =(($B$7*(1+$A25)-$B$8)*MAX(0,$B$9*(1+B$24*$A25))-($B$7-$B$8)*$B$9)*52 -> -109136.87 | C25: =(($B$7*(1+$A25)-$B$8)*MAX(0,$B$9*(1+C$24*$A25))-($B$7-$B$8)*$B$9)*52 -> -98289.535 | D25: =(($B$7*(1+$A25)-$B$8)*MAX(0,$B$9*(1+D$24*$A25))-($B$7-$B$8)*$B$9)*52 -> -87442.203 | E25: =(($B$7*(1+$A25)-$B$8)*MAX(0,$B$9*(1+E$24*$A25))-($B$7-$B$8)*$B$9)*52 -> -76594.871 | F25: =(($B$7*(1+$A25)-$B$8)*MAX(0,$B$9*(1+F$24*$A25))-($B$7-$B$8)*$B$9)*52 -> -65747.539
A26: -0.04 | B26: =(($B$7*(1+$A26)-$B$8)*MAX(0,$B$9*(1+B$24*$A26))-($B$7-$B$8)*$B$9)*52 -> -71958.017 | C26: =(($B$7*(1+$A26)-$B$8)*MAX(0,$B$9*(1+C$24*$A26))-($B$7-$B$8)*$B$9)*52 -> -63926.567 | D26: =(($B$7*(1+$A26)-$B$8)*MAX(0,$B$9*(1+D$24*$A26))-($B$7-$B$8)*$B$9)*52 -> -55895.118 | E26: =(($B$7*(1+$A26)-$B$8)*MAX(0,$B$9*(1+E$24*$A26))-($B$7-$B$8)*$B$9)*52 -> -47863.669 | F26: =(($B$7*(1+$A26)-$B$8)*MAX(0,$B$9*(1+F$24*$A26))-($B$7-$B$8)*$B$9)*52 -> -39832.22
A27: -0.02 | B27: =(($B$7*(1+$A27)-$B$8)*MAX(0,$B$9*(1+B$24*$A27))-($B$7-$B$8)*$B$9)*52 -> -35579.061 | C27: =(($B$7*(1+$A27)-$B$8)*MAX(0,$B$9*(1+C$24*$A27))-($B$7-$B$8)*$B$9)*52 -> -31163.389 | D27: =(($B$7*(1+$A27)-$B$8)*MAX(0,$B$9*(1+D$24*$A27))-($B$7-$B$8)*$B$9)*52 -> -26747.717 | E27: =(($B$7*(1+$A27)-$B$8)*MAX(0,$B$9*(1+E$24*$A27))-($B$7-$B$8)*$B$9)*52 -> -22332.045 | F27: =(($B$7*(1+$A27)-$B$8)*MAX(0,$B$9*(1+F$24*$A27))-($B$7-$B$8)*$B$9)*52 -> -17916.373
A28: 0 | B28: =(($B$7*(1+$A28)-$B$8)*MAX(0,$B$9*(1+B$24*$A28))-($B$7-$B$8)*$B$9)*52 -> 0 | C28: =(($B$7*(1+$A28)-$B$8)*MAX(0,$B$9*(1+C$24*$A28))-($B$7-$B$8)*$B$9)*52 -> 0 | D28: =(($B$7*(1+$A28)-$B$8)*MAX(0,$B$9*(1+D$24*$A28))-($B$7-$B$8)*$B$9)*52 -> 0 | E28: =(($B$7*(1+$A28)-$B$8)*MAX(0,$B$9*(1+E$24*$A28))-($B$7-$B$8)*$B$9)*52 -> 0 | F28: =(($B$7*(1+$A28)-$B$8)*MAX(0,$B$9*(1+F$24*$A28))-($B$7-$B$8)*$B$9)*52 -> 0
A29: 0.02 | B29: =(($B$7*(1+$A29)-$B$8)*MAX(0,$B$9*(1+B$24*$A29))-($B$7-$B$8)*$B$9)*52 -> 34779.166 | C29: =(($B$7*(1+$A29)-$B$8)*MAX(0,$B$9*(1+C$24*$A29))-($B$7-$B$8)*$B$9)*52 -> 29563.6 | D29: =(($B$7*(1+$A29)-$B$8)*MAX(0,$B$9*(1+D$24*$A29))-($B$7-$B$8)*$B$9)*52 -> 24348.033 | E29: =(($B$7*(1+$A29)-$B$8)*MAX(0,$B$9*(1+E$24*$A29))-($B$7-$B$8)*$B$9)*52 -> 19132.466 | F29: =(($B$7*(1+$A29)-$B$8)*MAX(0,$B$9*(1+F$24*$A29))-($B$7-$B$8)*$B$9)*52 -> 13916.9
A30: 0.04 | B30: =(($B$7*(1+$A30)-$B$8)*MAX(0,$B$9*(1+B$24*$A30))-($B$7-$B$8)*$B$9)*52 -> 68758.438 | C30: =(($B$7*(1+$A30)-$B$8)*MAX(0,$B$9*(1+C$24*$A30))-($B$7-$B$8)*$B$9)*52 -> 57527.41 | D30: =(($B$7*(1+$A30)-$B$8)*MAX(0,$B$9*(1+D$24*$A30))-($B$7-$B$8)*$B$9)*52 -> 46296.382 | E30: =(($B$7*(1+$A30)-$B$8)*MAX(0,$B$9*(1+E$24*$A30))-($B$7-$B$8)*$B$9)*52 -> 35065.354 | F30: =(($B$7*(1+$A30)-$B$8)*MAX(0,$B$9*(1+F$24*$A30))-($B$7-$B$8)*$B$9)*52 -> 23834.326
A31: 0.06 | B31: =(($B$7*(1+$A31)-$B$8)*MAX(0,$B$9*(1+B$24*$A31))-($B$7-$B$8)*$B$9)*52 -> 101937.82 | C31: =(($B$7*(1+$A31)-$B$8)*MAX(0,$B$9*(1+C$24*$A31))-($B$7-$B$8)*$B$9)*52 -> 83891.431 | D31: =(($B$7*(1+$A31)-$B$8)*MAX(0,$B$9*(1+D$24*$A31))-($B$7-$B$8)*$B$9)*52 -> 65845.047 | E31: =(($B$7*(1+$A31)-$B$8)*MAX(0,$B$9*(1+E$24*$A31))-($B$7-$B$8)*$B$9)*52 -> 47798.663 | F31: =(($B$7*(1+$A31)-$B$8)*MAX(0,$B$9*(1+F$24*$A31))-($B$7-$B$8)*$B$9)*52 -> 29752.28
A33: Promotion
A34: Discount | B34: 0.2
A35: Promotion length (weeks) | B35: 2
A36: Expected unit lift | B36: 0.5 | C36: Extra units during the promotion vs a normal week.
A37: Share of the discount the vendor pays | B37: 0.5
A38: Promotion price | B38: =B7*(1-B34) -> 25.582221
A39: Our margin per unit during the promotion | B39: =B38-B8+B7*B34*B37 -> 4.5028762
A40: Units per week during the promotion | B40: =B9*(1+B36) -> 1803.9
A41: Extra gross profit from the promotion | B41: =(B39*B40-(B7-B8)*B9)*B35 -> -2276.1359
A42: Break-even unit lift | B42: =IF(B39<=0,"Sells below cost",(B7-B8)/B39-1) -> 0.71016335 | C42: The lift the promotion needs to pay for itself.
A43: Markdown policy (Pricing and Margin Policy) | B43: =IF(B34>0.3,"Over the 30% cap: needs COO approval","Within the 30% cap") -> Within the 30% cap
A45: Extra gross profit from the promotion: discount (rows) by unit lift (columns)
...

Sheet Checks
A1: Checks
A2: Each check works a number out a second way. All should say OK.
A4: Check | B4: Value | C4: Worked out again | D4: Difference | E4: Status
A5: Sales: item lines tie to POS transactions | B5: =Actuals!C10 -> 1484042.4 | C5: =Actuals!D10 -> 1484042.4 | D5: =B5-C5 -> 0 | E5: =IF(ABS(D5)<=0.005*MAX(1,ABS(C5)),"OK","CHECK") -> OK
A6: Sales: categories tie to stores | B6: =Actuals!C25 -> 1484042.4 | C6: =Actuals!C10 -> 1484042.4 | D6: =B6-C6 -> 0 | E6: =IF(ABS(D6)<=0.005*MAX(1,ABS(C6)),"OK","CHECK") -> OK
A7: Cost of goods: categories tie to stores | B7: =Actuals!D25 -> 773286.12 | C7: =Actuals!E10 -> 773286.12 | D7: =B7-C7 -> 0 | E7: =IF(ABS(D7)<=0.005*MAX(1,ABS(C7)),"OK","CHECK") -> OK
A8: Channels add up to total sales | B8: =Actuals!B30+Actuals!B31 -> 1484042.4 | C8: =Actuals!C25 -> 1484042.4 | D8: =B8-C8 -> 0 | E8: =IF(ABS(D8)<=0.005*MAX(1,ABS(C8)),"OK","CHECK") -> OK
A9: New store: 60 months tie to the 5 yearly totals (EBITDA) | B9: =SUM('New Store'!$D$55:$BK$55) -> 3105800.7 | C9: =SUM('New Store'!B32:F32) -> 3105800.7 | D9: =B9-C9 -> 0 | E9: =IF(ABS(D9)<=0.005*MAX(1,ABS(C9)),"OK","CHECK") -> OK
A10: New store: sales reach 100% by the ramp month | B10: =INDEX('New Store'!$D$48:$BK$48,MIN(60,MAX(1,ramp_months))) -> 1 | C10: 1 | D10: =B10-C10 -> 0 | E10: =IF(ABS(D10)<=0.005*MAX(1,ABS(C10)),"OK","CHECK") -> OK
A11: Plan: 2029 new-store sales from the monthly model | B11: ='3-Year Plan'!E16 -> 17094203 | C11: =open_2027*SUMIF('New Store'!$D$47:$BK$47,3,'New Store'!$D$49:$BK$49)+open_2028*SUMIF('New Store'!$D$47:$BK$47,2,'New Store'!$D$49:$BK$49)+open_2029*SUMIF('New Store'!$D$47:$BK$47,1,'New Store'!$D$49:$BK$49) -> 17094203 | D11: =B11-C11 -> 0 | E11: =IF(ABS(D11)<=0.005*MAX(1,ABS(C11)),"OK","CHECK") -> OK
A12: Plan: cumulative cash equals the sum of yearly cash | B12: ='3-Year Plan'!E41 -> -246866.53 | C12: =SUM('3-Year Plan'!C40:E40) -> -246866.53 | D12: =B12-C12 -> 0 | E12: =IF(ABS(D12)<=0.005*MAX(1,ABS(C12)),"OK","CHECK") -> OK
A13: Plan: revenue lines add up to total revenue (2029) | B13: ='3-Year Plan'!E20 -> 41744430 | C13: ='3-Year Plan'!E14+'3-Year Plan'!E15+'3-Year Plan'!E16+'3-Year Plan'!E17+'3-Year Plan'!E18+'3-Year Plan'!E19 -> 41744430 | D13: =B13-C13 -> 0 | E13: =IF(ABS(D13)<=0.005*MAX(1,ABS(C13)),"OK","CHECK") -> OK
A14: Pricing: a 0% price change changes nothing | B14: =SUM(Pricing!B28:F28) -> 0 | C14: 0 | D14: =B14-C14 -> 0 | E14: =IF(ABS(D14)<=0.005*MAX(1,ABS(C14)),"OK","CHECK") -> OK
A15: Inputs: scenario name is valid | B15: =scenario -> Base | E15: =IF(ISNUMBER(MATCH(scenario,Inputs!$D$6:$F$6,0)),"OK","CHECK") -> OK
A16: Inputs: ramp and labor floor are within 0% to 100% | E16: =IF(AND(ramp_start>0,ramp_start<=1,ramp_months>=1,labor_floor>=0,labor_floor<=1),"OK","CHECK") -> OK
A17: Pricing: the category is in the Actuals list | B17: =category -> Meat & Seafood | E17: =IF(ISNUMBER(MATCH(category,category_list,0)),"OK","CHECK") -> OK
A19: Result | B19: =IF(COUNTIF(E5:E17,"OK")=ROWS(E5:E17),"All "&ROWS(E5:E17)&" checks pass",ROWS(E5:E17)-COUNTIF(E5:E17,"OK")&" of "&ROWS(E5:E17)&" checks need a look") -> All 13 checks pass
